Workbook

Sheet Simples
B2: Passagens para palestrantes e/ou conferencistas | D2: Unid. | E2: Quant. | F2: vl. Unit. | G2: Total Estimado
B3: Item
B4: Palestrantes Internacionais (Econômica) | D4: 2 | E4: 2 | F4: 3000 | G4: =F4*E4*D4 -> 12000
B5: Palestrantes Nacionais | D5: 3 | E5: 2 | F5: 1000 | G5: =F5*E5*D5 -> 6000
B6: Apresentadores de Minicursos | D6: 4 | E6: 2 | F6: 1000 | G6: =F6*E6*D6 -> 8000
B7: Coordenador de Comite de Programa | D7: 2 | E7: 2 | F7: 1750 | G7: =F7*E7*D7 -> 7000
B8: Coordenadores de Workshop/Minicursos | D8: 4 | E8: 2 | F8: 1000 | G8: =F8*E8*D8 -> 8000
B9: SubTotal | G9: =SUM(G4:G8) -> 41000
B11: Diárias para palestrantes e/ou conferencistas | D11: Unid. | E11: Quant. | F11: vl. Unit. | G11: Total Estimado
B12: Item
B13: Palestrantes Internacionais | D13: 2 | E13: 8 | F13: 187.83 | G13: =F13*E13*D13 -> 3005.28
B14: Palestrantes Nacionais | D14: 3 | E14: 8 | F14: 187.83 | G14: =F14*E14*D14 -> 4507.92
B15: Apresentadores de Minicursos | D15: 4 | E15: 4 | F15: 187.83 | G15: =F15*E15*D15 -> 3005.28
B16: Coordenador do Comite de Programa | D16: 2 | E16: 8 | F16: 187.83 | G16: =F16*E16*D16 -> 3005.28
B17: Coordenadores de Workshop | D17: 4 | E17: 8 | F17: 187.83 | G17: =F17*E17*D17 -> 6010.56
B18: SubTotal | G18: =SUM(G13:G17) -> 19534.32
B20: InfraEstrutura | D20: Unid. | E20: Quant. | F20: vl. Unit. | G20: Total Estimado
B21: Item
B22: Locação do Centro de Eventos (salas) | D22: 4 | E22: 4 | F22: 2340 | G22: =D22*E22*F22 -> 37440
B23: Locação de Projetores Multimidia | D23: 4 | E23: 4 | F23: 250 | G23: =F23*E23*D23 -> 4000
B24: Locação de Computadores para uso dos participantes | D24: 10 | E24: 4 | F24: 50 | G24: =F24*E24*D24 -> 2000
B25: Locação de InfraEstrutura de Redes | D25: 1 | E25: 4 | F25: 1750 | G25: =F25*E25*D25 -> 7000
B26: Locação de Equipamentos de Áudio e Sonorização | D26: 4 | E26: 4 | F26: 100 | G26: =F26*E26*D26 -> 1600
B27: Transfer Hoteis | D27: 17 | E27: 2 | F27: 80 | G27: =F27*E27*D27 -> 2720
B28: Serviços de Tradução Simultânea | D28: 1 | E28: 4 | F28: 1250 | G28: =F28*E28*D28 -> 5000
B29: SubTotal | G29: =SUM(G22:G28) -> 59760
B31: Serviços de Impressão/divulgação | D31: Unid. | E31: Quant. | F31: vl. Unit. | G31: Total Estimado
B32: Item
B33: Edição/Impressão de Programação Final | D33: 1 | E33: 400 | F33: 2.5 | G33: =F33*E33*D33 -> 1000
B34: Impressão de Cartazes | D34: 1 | E34: 400 | F34: 5 | G34: =F34*E34*D34 -> 2000
B35: Impressão de Faixas | D35: 1 | E35: 50 | F35: 20 | G35: =F35*E35*D35 -> 1000
B36: Impressão Material do MiniCursos | D36: 1 | E36: 400 | F36: 5 | G36: =F36*E36*D36 -> 2000
B37: Folder de Divulgação do Evento | D37: 1 | E37: 400 | F37: 2.5 | G37: =F37*E37*D37 -> 1000
B38: Editoração dos Anais | D38: 1 | E38: 1 | F38: 4000 | G38: =F38*E38*D38 -> 4000
B39: Produção de Mídia | D39: 1 | E39: 400 | F39: 5 | G39: =F39*E39*D39 -> 2000
B40: Aquisição de Material de Consumo | D40: 1 | E40: 1 | F40: 9500 | G40: 9500
B41: SubTotal | G41: =SUM(G33:G40) -> 22500
B43: Serviços de Terceiros | D43: Unid. | E43: Quant. | F43: vl. Unit. | G43: Total Estimado
B44: Item
B45: Confecção de Camisas | D45: 1 | E45: 400 | F45: 18 | G45: =F45*E45*D45 -> 7200
...

Sheet Completa
B2: Passagens para palestrantes e/ou conferencistas | D2: Unid. | E2: Quant. | F2: vl. Unit. | G2: Total Estimado | H2: FAPEAM | J2: CAPES | L2: CGI-BR | N2: CNPq | P2: Total Solicitado | Q2: Total Atendido
B3: Item | H3: Solicitado | I3: Atendido | J3: Solicitado | K3: Atendido | L3: Solicitado | M3: Atendido | N3: Solicitado | O3: Atendido
B4: Palestrantes Internacionais (Econômica) | D4: =Simples!D4 -> 2 | E4: =Simples!E4 -> 2 | F4: 3750 | G4: =F4*E4*D4 -> 15000 | H4: 0 | I4: 0 | J4: 7000 | K4: 0 | L4: 0 | M4: 0 | N4: 7000 | O4: 7000 | P4: =H4+J4+L4+N4 -> 14000 | Q4: =I4+K4+M4+O4 -> 7000
B5: Palestrantes Nacionais | D5: =Simples!D5 -> 3 | E5: =Simples!E5 -> 2 | F5: =Simples!F5 -> 1000 | G5: =F5*E5*D5 -> 6000 | H5: 0 | I5: 0 | J5: 0 | K5: 0 | L5: 0 | M5: 0 | N5: 0 | O5: 0 | P5: =H5+J5+L5+N5 -> 0 | Q5: =I5+K5+M5+O5 -> 0
B6: Apresentadores de Minicursos | D6: =Simples!D6 -> 4 | E6: =Simples!E6 -> 2 | F6: =Simples!F6 -> 1000 | G6: =F6*E6*D6 -> 8000 | H6: 0 | I6: 0 | J6: 7000 | K6: 0 | L6: 0 | M6: 0 | N6: =G6 -> 8000 | O6: 8000 | P6: =H6+J6+L6+N6 -> 15000 | Q6: =I6+K6+M6+O6 -> 8000
B7: Coordenador de Comite de Programa | D7: =Simples!D7 -> 2 | E7: =Simples!E7 -> 2 | F7: =Simples!F7 -> 1750 | G7: =F7*E7*D7 -> 7000 | H7: 0 | I7: 0 | J7: =2500+3500 -> 6000 | K7: 0 | L7: 0 | M7: 0 | N7: 0 | O7: 0 | P7: =H7+J7+L7+N7 -> 6000 | Q7: =I7+K7+M7+O7 -> 0
B8: Coordenadores de Workshop/Minicursos | D8: =Simples!D8 -> 4 | E8: =Simples!E8 -> 2 | F8: =Simples!F8 -> 1000 | G8: =F8*E8*D8 -> 8000 | H8: 0 | I8: 0 | J8: 0 | K8: 0 | L8: 0 | M8: 0 | N8: =G8 -> 8000 | O8: 0 | P8: =H8+J8+L8+N8 -> 8000 | Q8: =I8+K8+M8+O8 -> 0
B9: SubTotal | G9: =SUM(G4:G8) -> 44000 | H9: =SUM(H4:H8) -> 0 | I9: =SUM(I4:I8) -> 0 | J9: =SUM(J4:J8) -> 20000 | K9: =SUM(K4:K8) -> 0 | L9: =SUM(L4:L8) -> 0 | M9: =SUM(M4:M8) -> 0 | N9: =SUM(N4:N8) -> 23000 | ... Q9: =SUM(Q4:Q8) -> 15000
B11: Diárias para palestrantes e/ou conferencistas | D11: Unid. | E11: Quant. | F11: vl. Unit. | G11: Total Estimado | H11: FAPEAM | J11: CAPES | L11: CGI-BR | N11: CNPq | P11: Total Solicitado | Q11: Total Atendido
B12: Item | H12: Solicitado | I12: Atendido | J12: Solicitado | K12: Atendido | L12: Solicitado | M12: Atendido | N12: Solicitado | O12: Atendido
B13: Palestrantes Internacionais | D13: 2 | E13: 8 | F13: 187.83 | G13: =F13*E13*D13 -> 3005.28 | H13: 0 | I13: 0 | J13: 3005.28 | K13: 0 | L13: 0 | M13: 0 | N13: =G13 -> 3005.28 | O13: 0 | P13: =H13+J13+L13+N13 -> 6010.56 | Q13: =I13+K13+M13+O13 -> 0
B14: Palestrantes Nacionais | D14: 3 | E14: 8 | F14: 187.83 | G14: =F14*E14*D14 -> 4507.92 | H14: 0 | I14: 0 | J14: 1502.64 | K14: 0 | L14: 0 | M14: 0 | N14: 0 | O14: 0 | P14: =H14+J14+L14+N14 -> 1502.64 | Q14: =I14+K14+M14+O14 -> 0
B15: Apresentadores de Minicursos | D15: 4 | E15: 4 | F15: 187.83 | G15: =F15*E15*D15 -> 3005.28 | H15: 0 | I15: 0 | J15: 3005.28 | K15: 0 | L15: 0 | M15: 0 | N15: =G15 -> 3005.28 | O15: 0 | P15: =H15+J15+L15+N15 -> 6010.56 | Q15: =I15+K15+M15+O15 -> 0
B16: Coordenador do Comite de Programa | D16: 2 | E16: 8 | F16: 187.83 | G16: =F16*E16*D16 -> 3005.28 | H16: 0 | I16: 0 | J16: 1502.64 | K16: 0 | L16: 0 | M16: 0 | N16: 0 | O16: 0 | P16: =H16+J16+L16+N16 -> 1502.64 | Q16: =I16+K16+M16+O16 -> 0
B17: Coordenadores de Workshop | D17: 4 | E17: 8 | F17: 187.83 | G17: =F17*E17*D17 -> 6010.56 | H17: 0 | I17: 0 | J17: 3005.28 | K17: 0 | L17: 0 | M17: 0 | N17: =G17 -> 6010.56 | O17: 0 | P17: =H17+J17+L17+N17 -> 9015.84 | Q17: =I17+K17+M17+O17 -> 0
B18: SubTotal | G18: =SUM(G13:G17) -> 19534.32 | H18: =SUM(H13:H17) -> 0 | I18: =SUM(I13:I17) -> 0 | J18: =SUM(J13:J17) -> 12021.12 | K18: =SUM(K13:K17) -> 0 | L18: =SUM(L13:L17) -> 0 | M18: =SUM(M13:M17) -> 0 | N18: =SUM(N13:N17) -> 12021.12 | ... Q18: =SUM(Q13:Q17) -> 0
B20: InfraEstrutura | D20: Unid. | E20: Quant. | F20: vl. Unit. | G20: Total Estimado | H20: FAPEAM | J20: CAPES | L20: CGI-BR | N20: CNPq | P20: Total Solicitado | Q20: Total Atendido
B21: Item | H21: Solicitado | I21: Atendido | J21: Solicitado | K21: Atendido | L21: Solicitado | M21: Atendido | N21: Solicitado | O21: Atendido
B22: Locação do Centro de Eventos (salas) | D22: 4 | E22: 4 | F22: 2340 | G22: =D22*E22*F22 -> 37440 | H22: 0 | I22: 0 | J22: 22000 | K22: 22000 | L22: 42000 | M22: 42000 | N22: =G22 -> 37440 | O22: 0 | P22: =H22+J22+L22+N22 -> 101440 | Q22: =I22+K22+M22+O22 -> 64000
B23: Locação de Projetores Multimidia | D23: 4 | E23: 4 | F23: 250 | G23: =F23*E23*D23 -> 4000 | H23: 4250 | I23: 4250 | J23: 0 | K23: 0 | L23: 6000 | M23: 6000 | N23: 0 | O23: 0 | P23: =H23+J23+L23+N23 -> 10250 | Q23: =I23+K23+M23+O23 -> 10250
B24: Locação de Computadores para uso dos participantes | D24: 10 | E24: 4 | F24: 50 | G24: =F24*E24*D24 -> 2000 | H24: 0 | I24: 0 | J24: 0 | K24: 0 | L24: 0 | M24: 0 | N24: 0 | O24: 0 | P24: =H24+J24+L24+N24 -> 0 | Q24: =I24+K24+M24+O24 -> 0
B25: Locação de InfraEstrutura de Redes | D25: 1 | E25: 4 | F25: 1750 | G25: =F25*E25*D25 -> 7000 | H25: 0 | I25: 0 | J25: 4000 | K25: 4000 | L25: 6000 | M25: 6000 | N25: =G25 -> 7000 | O25: 0 | P25: =H25+J25+L25+N25 -> 17000 | Q25: =I25+K25+M25+O25 -> 10000
B26: Locação de Equipamentos de Áudio e Sonorização | D26: 4 | E26: 4 | F26: 100 | G26: =F26*E26*D26 -> 1600 | H26: 1250 | I26: 1250 | J26: 0 | K26: 0 | L26: 1000 | M26: 1000 | N26: 0 | O26: 0 | P26: =H26+J26+L26+N26 -> 2250 | Q26: =I26+K26+M26+O26 -> 2250
B27: Transfer Hoteis | D27: 17 | E27: 2 | F27: 80 | G27: =F27*E27*D27 -> 2720 | H27: 0 | I27: 0 | J27: 0 | K27: 0 | L27: 0 | M27: 0 | N27: 0 | O27: 0 | P27: =H27+J27+L27+N27 -> 0 | Q27: =I27+K27+M27+O27 -> 0
B28: Serviços de Tradução Simultânea | D28: 1 | E28: 4 | F28: 1250 | G28: =F28*E28*D28 -> 5000 | H28: 0 | I28: 0 | J28: 0 | K28: 0 | L28: 0 | M28: 0 | N28: 0 | O28: 0 | P28: =H28+J28+L28+N28 -> 0 | Q28: =I28+K28+M28+O28 -> 0
B29: SubTotal | G29: =SUM(G22:G28) -> 59760 | H29: =SUM(H20:H28) -> 5500 | I29: =SUM(I20:I28) -> 5500 | J29: =SUM(J20:J28) -> 26000 | K29: =SUM(K20:K28) -> 26000 | L29: =SUM(L20:L28) -> 55000 | M29: =SUM(M20:M28) -> 55000 | N29: =SUM(N20:N28) -> 44440 | O29: =SUM(O20:O28) -> 0 | P29: =SUM(P22:P28) -> 130940 | Q29: =SUM(Q22:Q28) -> 86500
B31: Serviços de Impressão/divulgação | D31: Unid. | E31: Quant. | F31: vl. Unit. | G31: Total Estimado | H31: FAPEAM | J31: CAPES | L31: CGI-BR | N31: CNPq | P31: Total Solicitado | Q31: Total Atendido
B32: Item | H32: Solicitado | I32: Atendido | J32: Solicitado | K32: Atendido | L32: Solicitado | M32: Atendido | N32: Solicitado | O32: Atendido
B33: Edição/Impressão de Programação Final | D33: 1 | E33: 400 | F33: 2.5 | G33: =F33*E33*D33 -> 1000 | H33: 0 | I33: 0 | J33: 0 | K33: 0 | L33: 3000 | M33: 3000 | N33: =G33 -> 1000 | O33: 0 | P33: =H33+J33+L33+N33 -> 4000 | Q33: =I33+K33+M33+O33 -> 3000
B34: Impressão de Cartazes | D34: 1 | E34: 400 | F34: 5 | G34: =F34*E34*D34 -> 2000 | H34: 1000 | I34: 1000 | J34: 0 | K34: 0 | L34: 5000 | M34: 5000 | N34: 1000 | O34: 0 | P34: =H34+J34+L34+N34 -> 7000 | Q34: =I34+K34+M34+O34 -> 6000
B35: Impressão de Faixas | D35: 1 | E35: 50 | F35: 20 | G35: =F35*E35*D35 -> 1000 | H35: 500 | I35: 500 | J35: 0 | K35: 0 | L35: 5000 | M35: 5000 | N35: 0 | O35: 0 | P35: =H35+J35+L35+N35 -> 5500 | Q35: =I35+K35+M35+O35 -> 5500
B36: Impressão Material do MiniCursos | D36: 1 | E36: 400 | F36: 5 | G36: =F36*E36*D36 -> 2000 | H36: 0 | I36: 0 | J36: 0 | K36: 0 | L36: 5000 | M36: 5000 | N36: =G36 -> 2000 | O36: 0 | P36: =H36+J36+L36+N36 -> 7000 | Q36: =I36+K36+M36+O36 -> 5000
B37: Folder de Divulgação do Evento | D37: 1 | E37: 400 | F37: 2.5 | G37: =F37*E37*D37 -> 1000 | H37: 1000 | I37: 1000 | J37: 0 | K37: 0 | L37: 1000 | M37: 1000 | N37: 0 | O37: 0 | P37: =H37+J37+L37+N37 -> 2000 | Q37: =I37+K37+M37+O37 -> 2000 | U37: 7.25 | V37: 400 ou 500
B38: Editoração dos Anais | D38: 1 | E38: 1 | F38: 4000 | G38: =F38*E38*D38 -> 4000 | H38: 0 | I38: 0 | J38: 0 | K38: 0 | L38: 3000 | M38: 3000 | N38: =G38 -> 4000 | O38: 0 | P38: =H38+J38+L38+N38 -> 7000 | Q38: =I38+K38+M38+O38 -> 3000 | U38: Cracha precisa de arte
B39: Produção de Mídia | D39: 1 | E39: 400 | F39: 5 | G39: =F39*E39*D39 -> 2000 | H39: 0 | I39: 0 | J39: 0 | K39: 0 | L39: 5000 | M39: 5000 | N39: =G39 -> 2000 | O39: 0 | P39: =H39+J39+L39+N39 -> 7000 | Q39: =I39+K39+M39+O39 -> 5000
B40: Aquisição de Material de Consumo | D40: 1 | E40: 1 | F40: 9500 | G40: 9500 | H40: 0 | I40: 0 | J40: 1978.88 | K40: 0 | L40: 2000 | M40: 2000 | N40: 0 | O40: 0 | P40: =H40+J40+L40+N40 -> 3978.88 | Q40: =I40+K40+M40+O40 -> 2000
B41: SubTotal | G41: =SUM(G33:G40) -> 22500 | H41: =SUM(H33:H40) -> 2500 | I41: =SUM(I33:I40) -> 2500 | J41: =SUM(J33:J40) -> 1978.88 | K41: =SUM(K33:K40) -> 0 | L41: =SUM(L33:L40) -> 29000 | M41: =SUM(M33:M40) -> 29000 | N41: =SUM(N33:N40) -> 10000 | ... Q41: =SUM(Q33:Q40) -> 31500
B43: Serviços de Terceiros | D43: Unid. | E43: Quant. | F43: vl. Unit. | G43: Total Estimado | H43: FAPEAM | J43: CAPES | L43: CGI-BR | N43: CNPq | P43: Total Solicitado | Q43: Total Atendido
B44: Item | H44: Solicitado | I44: Atendido | J44: Solicitado | K44: Atendido | L44: Solicitado | M44: Atendido | N44: Solicitado | O44: Atendido
B45: Confecção de Camisas | D45: 1 | E45: 400 | F45: 18 | G45: =F45*E45*D45 -> 7200 | H45: 5940 | I45: 5940 | J45: 0 | K45: 0 | L45: 0 | M45: 0 | N45: 0 | O45: 0 | P45: =H45+J45+L45+N45 -> 5940 | Q45: =I45+K45+M45+O45 -> 5940
...

Sheet Receitas
A1: RECEITAS SBSEG 2013
A2: Previsão | B2: Valores | C2: Arrecadado | D2: Valores
A3: Comitê Gestor Internet | B3: 100000 | C3: Comitê Gestor Internet (Patrocínio) | D3: 100000
A4: Inscrições | B4: 45000 | C4: CNPq | D4: 15000
A5: CNPq | B5: 49990 | C5: CAPES | D5: 45000
A6: CAPES | B6: 60000 | C6: FAPEAM | D6: 29850
A7: Patrocínios | B7: 40000 | C7: Inscrições | D7: =38998 -> 38998
A8: FAPEAM (Fundação de Amparo a Pesquisa do Estado do Amazonas) | B8: 25000 | C8: INTEL (Patrocínio) | D8: 10000
C9: START (Patrocínio) | D9: 2500
A11: Total | B11: =SUM(B3:B10) -> 319990 | C11: SubTotal | D11: =SUM(D3:D9) -> 241348

Sheet Despesas
A1: Passagens | C1: Quant. | D1: Valor Unit. | E1: Valor Total | F1: Fonte de Despesa | G1: Empresa | H1: Status
A2: Matt Bishop - Palestrante Internacional | C2: 1 | D2: 4856.46 | E2: =C2*D2 -> 4856.46 | F2: CAPES | G2: Paradise (Delta Air Lines) | H2: PAGO
A3: Evandro Della Vecchia - Minicurso 1 | C3: 1 | D3: 1824.17 | E3: =C3*D3 -> 1824.17 | F3: CNPq | G3: Paradise (Azul) | H3: PAGO
A4: Marlon Domenech - Minicurso 4 | C4: 1 | D4: 1011.28 | E4: =C4*D4 -> 1011.28 | F4: CNPq | G4: Paradise (TAM) | H4: PAGO
A5: Edna Canedo - Coordenadora FSC | C5: 1 | D5: =919.38+73.83+100 -> 1093.21 | E5: =C5*D5 -> 1093.21 | F5: CNPq | G5: Paradise (TAM) | H5: PAGO
A6: Cinthia Freitas - Coordenadora WFC | C6: 1 | D6: 1730.33 | E6: =C6*D6 -> 1730.33 | F6: CNPq | G6: Paradise (TAM) | H6: PAGO
A7: Rossana Andrade - Coordenadora Minucursos | C7: 1 | D7: =660.84+768.36 -> 1429.2 | E7: =C7*D7 -> 1429.2 | F7: CNPq | G7: Paradise (TAM + GOL) | H7: PAGO
A8: Geovandro Pereira - Minicurso 2 | C8: 1 | D8: 959.88 | E8: =C8*D8 -> 959.88 | F8: CNPq | G8: Paradise (GOL) | H8: PAGO
A9: Raul Ceretta - Coordenador TP | C9: 1 | D9: 1842.3 | E9: =C9*D9 -> 1842.3 | F9: CNPq | G9: Paradise (TAM) | H9: PAGO
A10: Willer Santos - Minicurso 3 | C10: 1 | D10: 1320.33 | E10: =C10*D10 -> 1320.33 | F10: CNPq | G10: Paradise (TAM) | H10: PAGO
A11: Rafael Timoteo Souza Junior | C11: 1 | D11: 1113.72 | E11: =C11*D11 -> 1113.72 | F11: CNPq | G11: Paradise (TAM) | H11: PAGO
A12: Fabian Monrose - Palestra Internacional | C12: 1 | D12: 6035 | E12: =C12*D12 -> 6035 | F12: CAPES | G12: Paradise (Ameircan) | H12: Em andamento
A13: Jorge de A. Lambert - WFC e FSC | C13: 1 | D13: 2349.53 | E13: =C13*D13 -> 2349.53 | F13: Patrocinios | G13: Paradise (TAM) | H13: Em andamento
A14: Marcelo Caldeira Ruback - WFC e FSC | C14: 1 | D14: 2349.53 | E14: =C14*D14 -> 2349.53 | F14: Patrocinios | G14: Paradise (TAM) | H14: Em andamento
A15: Otávio Carlos Cunha da Silva - FSC | C15: 1 | D15: 1794.47 | E15: =C15*D15 -> 1794.47 | F15: Patrocinios | G15: Paradise (TAM) | H15: Em andamento
A16: Michel Abdalla - Coordenador TP | C16: 1 | D16: 2183.2 | E16: =C16*D16 -> 2183.2 | F16: Patrocinios | G16: Paradise (GOL) | H16: Em andamento
A17: Luiz Cláudio Gomes Gonçalves - FSC | C17: 1 | D17: 1724.81 | E17: =C17*D17 -> 1724.81 | F17: Patrocinios | G17: Paradise (GOL) | H17: Em andamento
A18: SubTotal | C18: =SUM(C2:C17) -> 16 | D18: =SUM(D2:D17) -> 33617.42 | E18: =SUM(E2:E17) -> 33617.42
A20: Diárias/Hospedagem para palestrantes | C20: Quant. | D20: Valor Unit. | E20: Valor Total | F20: Fonte de Despesa | G20: Empresa | H20: Status
A21: Matt Bishop - Palestrante Internacional | C21: 6 | D21: 265.2 | E21: =C21*D21 -> 1591.2 | F21: CAPES | G21: Park Suites Manaus | H21: Em andamento
A22: Fabian Monrose - Palestra Internacional | C22: 4 | D22: 265.2 | E22: =C22*D22 -> 1060.8 | F22: Patrocínios | G22: Park Suites Manaus | H22: PAGO
A23: Anderson Nascimento - Coordenador Palestras | C23: 7 | D23: 265.2 | E23: =C23*D23 -> 1856.4 | F23: Patrocínios | G23: Park Suites Manaus | H23: Em andamento
A24: Evandro Della Vecchia - Minicurso 1 | C24: 2 | D24: 200 | E24: =C24*D24 -> 400 | F24: CAPES | H24: Em andamento
A25: Marlon Domenech - Minicurso 4 | C25: 2 | D25: 200 | E25: =C25*D25 -> 400 | F25: CAPES | H25: Em andamento
A26: Willer Santos - Minicurso 3 | C26: 2 | D26: 200 | E26: =C26*D26 -> 400 | F26: CAPES | H26: Em andamento
A27: Geovandro Pereira - Minicurso 2 | C27: 2 | D27: 200 | E27: =C27*D27 -> 400 | F27: CAPES | H27: Em andamento
A28: Edna Canedo - Coordenadora FSC | C28: 7 | D28: =169.32 -> 169.32 | E28: =(C28*D28)+((C28*D28)*0.12) -> 1327.4688 | F28: Patrocínios | G28: Comfort Hotel | H28: PAGO
A29: Cinthia Freitas - Coordenadora WFC | C29: 4 | D29: =169.32 -> 169.32 | E29: =(C29*D29)+((C29*D29)*0.12) -> 758.5536 | F29: Patrocínios | G29: Comfort Hotel | H29: PAGO
A30: Rossana Andrade - Coordenadora Minucursos | C30: 4 | D30: =169.32 -> 169.32 | E30: =(C30*D30)+((C30*D30)*0.12) -> 758.5536 | F30: Patrocínios | G30: Comfort Hotel | H30: PAGO
A31: Raul Ceretta - Coordenador TP | C31: 4 | D31: =169.32 -> 169.32 | E31: =(C31*D31)+((C31*D31)*0.12) -> 758.5536 | F31: Patrocínios | G31: Comfort Hotel | H31: PAGO
A32: Rafael Timoteo Souza Junior | C32: 4 | D32: =169.32 -> 169.32 | E32: =(C32*D32)+((C32*D32)*0.12) -> 758.5536 | F32: Patrocínios | G32: Comfort Hotel | H32: PAGO
A33: Jorge de A. Lambert - WFC e FSC | C33: 1 | D33: =169.32 -> 169.32 | E33: =(C33*D33)+((C33*D33)*0.12) -> 189.6384 | F33: Patrocínios | G33: Comfort Hotel | H33: PAGO
A34: Marcelo Caldeira Ruback - WFC e FSC | C34: 1 | D34: =169.32 -> 169.32 | E34: =(C34*D34)+((C34*D34)*0.12) -> 189.6384 | F34: Patrocínios | G34: Comfort Hotel | H34: PAGO
A35: Otávio Carlos Cunha da Silva - FSC | C35: 2 | D35: =169.32 -> 169.32 | E35: =(C35*D35)+((C35*D35)*0.12) -> 379.2768 | F35: Patrocínios | G35: Comfort Hotel | H35: PAGO
A36: Michel Abdalla - Coordenador TP | C36: 2 | D36: =169.32 -> 169.32 | E36: =(C36*D36)+((C36*D36)*0.12) -> 379.2768 | F36: Patrocínios | G36: Comfort Hotel | H36: PAGO
A37: Luiz Cláudio Gomes Gonçalves - FSC | C37: 2 | D37: =169.32 -> 169.32 | E37: =(C37*D37)+((C37*D37)*0.12) -> 379.2768 | F37: Patrocínios | G37: Comfort Hotel | H37: PAGO
A38: SubTotal | C38: =SUM(C21:C37) -> 56 | D38: =SUM(D21:D37) -> 3288.8 | E38: =SUM(E21:E37) -> 11987.19 | I38: =SUM(E28:E37) -> 5878.7904
A40: InfraEstrutura | C40: Quant. | D40: Valor Unit. | E40: Valor Total | F40: Fonte de Despesa | G40: Empresa | H40: Status
A41: Locação do Centro de Eventos (5 salas) | C41: 1 | D41: 31158 | E41: =C41*D41 -> 31158 | F41: CAPES | G41: Studio 5 | H41: PAGO
A42: Locação de Projetores Multimidia | C42: 2 | D42: 2098 | E42: =C42*D42 -> 4196 | F42: Patrocínios | G42: Amazon Print | H42: PAGO
...

Sheet Pagamentos
A1: CAPES
A2: Item de Despesa | C2: Quant. | D2: Valor Unit. | E2: Valor Total | F2: Empresa
A3: Passagem Aérea (Matt Bishop - Palestrante Internacional) | C3: 1 | D3: 4856.46 | E3: =C3*D3 -> 4856.46 | F3: Paradise (Delta Air Lines)
A4: Locação do Centro de Eventos (5 salas) | C4: 1 | D4: 31158 | E4: =C4*D4 -> 31158 | F4: Studio 5 Centro de Convenções
A5: Passagem Aérea (Fabian Monrose - Palestra Internacional) | C5: 1 | D5: 6023.15 | E5: =C5*D5 -> 6023.15 | F5: Paradise (AA)
A6: Hospedagem - Fabian Monrose - Palestrante Internacional | C6: 4 | D6: 269.28 | E6: =C6*D6 -> 1077.12 | F6: Park Suites
A7: Hospedagem - Evandro Della Vecchia | C7: 2 | D7: 200 | E7: =C7*D7 -> 400
A8: Hospedagem - Geovandro Pereira | C8: 2 | D8: 200 | E8: =C8*D8 -> 400
A9: Hospedagem - Willer Ferreira | C9: 2 | D9: 200 | E9: =C9*D9 -> 400
A10: Hospedagem - Marlon Domenech | C10: 2 | D10: 200 | E10: =C10*D10 -> 400
E11: =SUM(E3:E10) -> 44714.73 | G11: =45000-E11 -> 285.27
A13: CNPq
A14: Item de Despesa | C14: Quant. | D14: Valor Unit. | E14: Valor Total | F14: Empresa
A15: Passagem Aérea (Evandro Della Vecchia - Minicurso 1) | C15: 1 | D15: 1824.17 | E15: =C15*D15 -> 1824.17 | F15: Paradise (Azul) | G15: ok
A16: Passagem Aérea (Marlon Domenech - Minicurso 4) | C16: 1 | D16: 1011.28 | E16: =C16*D16 -> 1011.28 | F16: Paradise (TAM) | G16: ok
A17: Passagem Aérea (Edna Canedo - Coordenadora FSC) | C17: 1 | D17: =919.38+73.83+100 -> 1093.21 | E17: =C17*D17 -> 1093.21 | F17: Paradise (TAM) | G17: ok
A18: Passagem Aérea (Cinthia Freitas - Coordenadora WFC) | C18: 1 | D18: 1730.33 | E18: =C18*D18 -> 1730.33 | F18: Paradise (TAM) | G18: ok
A19: Passagem Aérea (Rossana Andrade - Coordenadora Minucursos) | C19: 1 | D19: =660.84+768.36 -> 1429.2 | E19: =C19*D19 -> 1429.2 | F19: Paradise (TAM + GOL) | G19: ok
A20: Passagem Aérea (Geovandro Pereira - Minicurso 2) | C20: 1 | D20: 959.88 | E20: =C20*D20 -> 959.88 | F20: Paradise (GOL) | G20: ok
A21: Passagem Aérea (Raul Ceretta - Coordenador TP) | C21: 1 | D21: 1842.3 | E21: =C21*D21 -> 1842.3 | F21: Paradise (TAM) | G21: ok
A22: Passagem Aérea (Willer Santos - Minicurso 3) | C22: 1 | D22: 1320.33 | E22: =C22*D22 -> 1320.33 | F22: Paradise (TAM) | G22: ok
A23: Passagem Aérea (Rafael Timoteo Souza Junior - Coordenador FSC) | C23: 1 | D23: 1113.72 | E23: =C23*D23 -> 1113.72 | F23: Paradise (TAM) | G23: ok
A24: Impressão de Cartazes | C24: 1 | D24: 230 | E24: =C24*D24 -> 230 | F24: Multicom | G24: ok
A25: Impressão de Cartazes | C25: 1 | D25: 230 | E25: =C25*D25 -> 230 | F25: Copycolor | G25: ok
A26: Toner | C26: 1 | D26: 1942.71 | E26: =C26*D26 -> 1942.71 | F26: Loja Lexmark | G26: ok
A28: SubTotal | E28: =SUM(E15:E26) -> 14727.13 | G28: =15000-E28 -> 272.87
A30: FAPEAM - SBSeg
A31: Item de Despesa | C31: Quant. | D31: Valor Unit. | E31: Valor Total | F31: Empresa
A32: Impressão de Cartazes | C32: 1 | D32: 855 | E32: =C32*D32 -> 855 | F32: Reprox | G32: ok
A33: Impressão de Cartazes | C33: 1 | D33: 230 | E33: =C33*D33 -> 230 | F33: Multicom | G33: ok
A34: Brindes | C34: 50 | D34: 1 | E34: =C34*D34 -> 50 | G34: ok
A35: Brindes | C35: 300 | D35: 1.5 | E35: =C35*D35 -> 450
A36: Crachá | C36: 400 | D36: 1 | E36: =C36*D36 -> 400 | F36: Ecopapelaria | G36: ok
A37: Camisas | C37: 320 | D37: 17 | E37: =C37*D37 -> 5440 | F37: Mark Design | G37: ok
A38: CD dos Anais | C38: 300 | D38: 5 | E38: =C38*D38 -> 1500
A39: Confecção de Pastas/bolsas | C39: 270 | D39: 12 | E39: =C39*D39 -> 3240 | F39: Zobessa | G39: ok
C40: 30 | D40: 28 | E40: =C40*D40 -> 840
A41: Traslado | C41: 19 | D41: 95 | E41: =C41*D41 -> 1805 | F41: APUI | G41: ok
A42: Impressão dos Minicursos | C42: 120 | D42: 19.35 | E42: =C42*D42 -> 2322 | F42: Cesart Grafica | G42: ok
A43: Impressão de Banners (70x90) | C43: 4 | D43: 38 | E43: =C43*D43 -> 152 | G43: ok
...

Sheet Sheet2
