Workbook

Sheet Simples
B2: Passagens para palestrantes e/ou conferencistas | D2: Unid. | E2: Quant. | F2: vl. Unit. | G2: Total Estimado
B3: Item
B4: Palestrantes Internacionais (Econômica) | D4: 2 | E4: 2 | F4: 3000 | G4: =F4*E4*D4 -> 12000
B5: Palestrantes Nacionais | D5: 3 | E5: 2 | F5: 1000 | G5: =F5*E5*D5 -> 6000
B6: Apresentadores de Minicursos | D6: 4 | E6: 2 | F6: 1000 | G6: =F6*E6*D6 -> 8000
B7: Coordenador de Comite de Programa | D7: 2 | E7: 2 | F7: 1750 | G7: =F7*E7*D7 -> 7000
B8: Coordenadores de Workshop/Minicursos | D8: 4 | E8: 2 | F8: 1000 | G8: =F8*E8*D8 -> 8000
B9: SubTotal | G9: =SUM(G4:G8) -> 41000
B11: Diárias para palestrantes e/ou conferencistas | D11: Unid. | E11: Quant. | F11: vl. Unit. | G11: Total Estimado
B12: Item
B13: Palestrantes Internacionais | D13: 2 | E13: 8 | F13: 187.83 | G13: =F13*E13*D13 -> 3005.28
B14: Palestrantes Nacionais | D14: 3 | E14: 8 | F14: 187.83 | G14: =F14*E14*D14 -> 4507.92
B15: Apresentadores de Minicursos | D15: 4 | E15: 4 | F15: 187.83 | G15: =F15*E15*D15 -> 3005.28
B16: Coordenador do Comite de Programa | D16: 2 | E16: 8 | F16: 187.83 | G16: =F16*E16*D16 -> 3005.28
B17: Coordenadores de Workshop | D17: 4 | E17: 8 | F17: 187.83 | G17: =F17*E17*D17 -> 6010.56
B18: SubTotal | G18: =SUM(G13:G17) -> 19534.32
B20: InfraEstrutura | D20: Unid. | E20: Quant. | F20: vl. Unit. | G20: Total Estimado
B21: Item
B22: Locação do Centro de Eventos (salas) | D22: 4 | E22: 4 | F22: 2340 | G22: =D22*E22*F22 -> 37440
B23: Locação de Projetores Multimidia | D23: 4 | E23: 4 | F23: 250 | G23: =F23*E23*D23 -> 4000
B24: Locação de Computadores para uso dos participantes | D24: 10 | E24: 4 | F24: 50 | G24: =F24*E24*D24 -> 2000
B25: Locação de InfraEstrutura de Redes | D25: 1 | E25: 4 | F25: 1750 | G25: =F25*E25*D25 -> 7000
B26: Locação de Equipamentos de Áudio e Sonorização | D26: 4 | E26: 4 | F26: 100 | G26: =F26*E26*D26 -> 1600
B27: Transfer Hoteis | D27: 17 | E27: 2 | F27: 80 | G27: =F27*E27*D27 -> 2720
B28: Serviços de Tradução Simultânea | D28: 1 | E28: 4 | F28: 1250 | G28: =F28*E28*D28 -> 5000
B29: SubTotal | G29: =SUM(G22:G28) -> 59760
B31: Serviços de Impressão/divulgação | D31: Unid. | E31: Quant. | F31: vl. Unit. | G31: Total Estimado
B32: Item
B33: Edição/Impressão de Programação Final | D33: 1 | E33: 400 | F33: 2.5 | G33: =F33*E33*D33 -> 1000
B34: Impressão de Cartazes | D34: 1 | E34: 400 | F34: 5 | G34: =F34*E34*D34 -> 2000
B35: Impressão de Faixas | D35: 1 | E35: 50 | F35: 20 | G35: =F35*E35*D35 -> 1000
B36: Impressão Material do MiniCursos | D36: 1 | E36: 400 | F36: 5 | G36: =F36*E36*D36 -> 2000
B37: Folder de Divulgação do Evento | D37: 1 | E37: 400 | F37: 2.5 | G37: =F37*E37*D37 -> 1000
B38: Editoração dos Anais | D38: 1 | E38: 1 | F38: 4000 | G38: =F38*E38*D38 -> 4000
B39: Produção de Mídia | D39: 1 | E39: 400 | F39: 5 | G39: =F39*E39*D39 -> 2000
B40: Aquisição de Material de Consumo | D40: 1 | E40: 1 | F40: 9500 | G40: 9500
B41: SubTotal | G41: =SUM(G33:G40) -> 22500
B43: Serviços de Terceiros | D43: Unid. | E43: Quant. | F43: vl. Unit. | G43: Total Estimado
B44: Item
B45: Confecção de Camisas | D45: 1 | E45: 400 | F45: 18 | G45: =F45*E45*D45 -> 7200
...

Sheet Completa
B2: Passagens para palestrantes e/ou conferencistas | D2: Unid. | E2: Quant. | F2: vl. Unit. | G2: Total Estimado | H2: FAPEAM | J2: CAPES | L2: CGI-BR | N2: CNPq | P2: Total Solicitado | Q2: Total Atendido
B3: Item | H3: Solicitado | I3: Atendido | J3: Solicitado | K3: Atendido | L3: Solicitado | M3: Atendido | N3: Solicitado | O3: Atendido
B4: Palestrantes Internacionais (Econômica) | D4: =Simples!D4 -> 2 | E4: =Simples!E4 -> 2 | F4: =Simples!F4 -> 3000 | G4: =F4*E4*D4 -> 12000 | H4: 0 | I4: 0 | J4: 0 | K4: 0 | L4: 0 | M4: 0 | N4: 7000 | O4: 0 | P4: =H4+J4+L4+N4 -> 7000 | Q4: =I4+K4+M4+O4 -> 0
B5: Palestrantes Nacionais | D5: =Simples!D5 -> 3 | E5: =Simples!E5 -> 2 | F5: =Simples!F5 -> 1000 | G5: =F5*E5*D5 -> 6000 | H5: 0 | I5: 0 | J5: 0 | K5: 0 | L5: 0 | M5: 0 | N5: 0 | O5: 0 | P5: =H5+J5+L5+N5 -> 0 | Q5: =I5+K5+M5+O5 -> 0
B6: Apresentadores de Minicursos | D6: =Simples!D6 -> 4 | E6: =Simples!E6 -> 2 | F6: =Simples!F6 -> 1000 | G6: =F6*E6*D6 -> 8000 | H6: 0 | I6: 0 | J6: 0 | K6: 0 | L6: 0 | M6: 0 | N6: =G6 -> 8000 | O6: 0 | P6: =H6+J6+L6+N6 -> 8000 | Q6: =I6+K6+M6+O6 -> 0
B7: Coordenador de Comite de Programa | D7: =Simples!D7 -> 2 | E7: =Simples!E7 -> 2 | F7: =Simples!F7 -> 1750 | G7: =F7*E7*D7 -> 7000 | H7: 0 | I7: 0 | J7: 0 | K7: 0 | L7: 0 | M7: 0 | N7: 0 | O7: 0 | P7: =H7+J7+L7+N7 -> 0 | Q7: =I7+K7+M7+O7 -> 0
B8: Coordenadores de Workshop/Minicursos | D8: =Simples!D8 -> 4 | E8: =Simples!E8 -> 2 | F8: =Simples!F8 -> 1000 | G8: =F8*E8*D8 -> 8000 | H8: 0 | I8: 0 | J8: 0 | K8: 0 | L8: 0 | M8: 0 | N8: =G8 -> 8000 | O8: 0 | P8: =H8+J8+L8+N8 -> 8000 | Q8: =I8+K8+M8+O8 -> 0
B9: SubTotal | G9: =SUM(G4:G8) -> 41000 | H9: =SUM(H4:H8) -> 0 | I9: =SUM(I4:I8) -> 0 | J9: =SUM(J4:J8) -> 0 | K9: =SUM(K4:K8) -> 0 | L9: =SUM(L4:L8) -> 0 | M9: =SUM(M4:M8) -> 0 | N9: =SUM(N4:N8) -> 23000 | ... Q9: =SUM(Q4:Q8) -> 0
B11: Diárias para palestrantes e/ou conferencistas | D11: Unid. | E11: Quant. | F11: vl. Unit. | G11: Total Estimado | H11: FAPEAM | J11: CAPES | L11: CGI-BR | N11: CNPq | P11: Total Solicitado | Q11: Total Atendido
B12: Item | H12: Solicitado | I12: Atendido | J12: Solicitado | K12: Atendido | L12: Solicitado | M12: Atendido | N12: Solicitado | O12: Atendido
B13: Palestrantes Internacionais | D13: 2 | E13: 8 | F13: 187.83 | G13: =F13*E13*D13 -> 3005.28 | H13: 0 | I13: 0 | J13: 0 | K13: 0 | L13: 0 | M13: 0 | N13: =G13 -> 3005.28 | O13: 0 | P13: =H13+J13+L13+N13 -> 3005.28 | Q13: =I13+K13+M13+O13 -> 0
B14: Palestrantes Nacionais | D14: 3 | E14: 8 | F14: 187.83 | G14: =F14*E14*D14 -> 4507.92 | H14: 0 | I14: 0 | J14: 0 | K14: 0 | L14: 0 | M14: 0 | N14: 0 | O14: 0 | P14: =H14+J14+L14+N14 -> 0 | Q14: =I14+K14+M14+O14 -> 0
B15: Apresentadores de Minicursos | D15: 4 | E15: 4 | F15: 187.83 | G15: =F15*E15*D15 -> 3005.28 | H15: 0 | I15: 0 | J15: 0 | K15: 0 | L15: 0 | M15: 0 | N15: =G15 -> 3005.28 | O15: 0 | P15: =H15+J15+L15+N15 -> 3005.28 | Q15: =I15+K15+M15+O15 -> 0
B16: Coordenador do Comite de Programa | D16: 2 | E16: 8 | F16: 187.83 | G16: =F16*E16*D16 -> 3005.28 | H16: 0 | I16: 0 | J16: 0 | K16: 0 | L16: 0 | M16: 0 | N16: 0 | O16: 0 | P16: =H16+J16+L16+N16 -> 0 | Q16: =I16+K16+M16+O16 -> 0
B17: Coordenadores de Workshop | D17: 4 | E17: 8 | F17: 187.83 | G17: =F17*E17*D17 -> 6010.56 | H17: 0 | I17: 0 | J17: 0 | K17: 0 | L17: 0 | M17: 0 | N17: =G17 -> 6010.56 | O17: 0 | P17: =H17+J17+L17+N17 -> 6010.56 | Q17: =I17+K17+M17+O17 -> 0
B18: SubTotal | G18: =SUM(G13:G17) -> 19534.32 | H18: =SUM(H13:H17) -> 0 | I18: =SUM(I13:I17) -> 0 | J18: =SUM(J13:J17) -> 0 | K18: =SUM(K13:K17) -> 0 | L18: =SUM(L13:L17) -> 0 | M18: =SUM(M13:M17) -> 0 | N18: =SUM(N13:N17) -> 12021.12 | ... Q18: =SUM(Q13:Q17) -> 0
B20: InfraEstrutura | D20: Unid. | E20: Quant. | F20: vl. Unit. | G20: Total Estimado | H20: FAPEAM | J20: CAPES | L20: CGI-BR | N20: CNPq | P20: Total Solicitado | Q20: Total Atendido
B21: Item | H21: Solicitado | I21: Atendido | J21: Solicitado | K21: Atendido | L21: Solicitado | M21: Atendido | N21: Solicitado | O21: Atendido
B22: Locação do Centro de Eventos (salas) | D22: 4 | E22: 4 | F22: 2340 | G22: =D22*E22*F22 -> 37440 | H22: 0 | I22: 0 | J22: 0 | K22: 0 | L22: 0 | M22: 0 | N22: =G22 -> 37440 | O22: 0 | P22: =H22+J22+L22+N22 -> 37440 | Q22: =I22+K22+M22+O22 -> 0
B23: Locação de Projetores Multimidia | D23: 4 | E23: 4 | F23: 250 | G23: =F23*E23*D23 -> 4000 | H23: 4250 | I23: 4250 | J23: 0 | K23: 0 | L23: 0 | M23: 0 | N23: 0 | O23: 0 | P23: =H23+J23+L23+N23 -> 4250 | Q23: =I23+K23+M23+O23 -> 4250
B24: Locação de Computadores para uso dos participantes | D24: 10 | E24: 4 | F24: 50 | G24: =F24*E24*D24 -> 2000 | H24: 0 | I24: 0 | J24: 0 | K24: 0 | L24: 0 | M24: 0 | N24: 0 | O24: 0 | P24: =H24+J24+L24+N24 -> 0 | Q24: =I24+K24+M24+O24 -> 0
B25: Locação de InfraEstrutura de Redes | D25: 1 | E25: 4 | F25: 1750 | G25: =F25*E25*D25 -> 7000 | H25: 0 | I25: 0 | J25: 0 | K25: 0 | L25: 0 | M25: 0 | N25: =G25 -> 7000 | O25: 0 | P25: =H25+J25+L25+N25 -> 7000 | Q25: =I25+K25+M25+O25 -> 0
B26: Locação de Equipamentos de Áudio e Sonorização | D26: 4 | E26: 4 | F26: 100 | G26: =F26*E26*D26 -> 1600 | H26: 1250 | I26: 1250 | J26: 0 | K26: 0 | L26: 0 | M26: 0 | N26: 0 | O26: 0 | P26: =H26+J26+L26+N26 -> 1250 | Q26: =I26+K26+M26+O26 -> 1250
B27: Transfer Hoteis | D27: 17 | E27: 2 | F27: 80 | G27: =F27*E27*D27 -> 2720 | H27: 0 | I27: 0 | J27: 0 | K27: 0 | L27: 0 | M27: 0 | N27: 0 | O27: 0 | P27: =H27+J27+L27+N27 -> 0 | Q27: =I27+K27+M27+O27 -> 0
B28: Serviços de Tradução Simultânea | D28: 1 | E28: 4 | F28: 1250 | G28: =F28*E28*D28 -> 5000 | H28: 0 | I28: 0 | J28: 0 | K28: 0 | L28: 0 | M28: 0 | N28: 0 | O28: 0 | P28: =H28+J28+L28+N28 -> 0 | Q28: =I28+K28+M28+O28 -> 0
B29: SubTotal | G29: =SUM(G22:G28) -> 59760 | H29: =SUM(H20:H28) -> 5500 | I29: =SUM(I20:I28) -> 5500 | J29: =SUM(J20:J28) -> 0 | K29: =SUM(K20:K28) -> 0 | L29: =SUM(L20:L28) -> 0 | M29: =SUM(M20:M28) -> 0 | N29: =SUM(N20:N28) -> 44440 | O29: =SUM(O20:O28) -> 0 | P29: =SUM(P22:P28) -> 49940 | Q29: =SUM(Q22:Q28) -> 5500
B31: Serviços de Impressão/divulgação | D31: Unid. | E31: Quant. | F31: vl. Unit. | G31: Total Estimado | H31: FAPEAM | J31: CAPES | L31: CGI-BR | N31: CNPq | P31: Total Solicitado | Q31: Total Atendido
B32: Item | H32: Solicitado | I32: Atendido | J32: Solicitado | K32: Atendido | L32: Solicitado | M32: Atendido | N32: Solicitado | O32: Atendido
B33: Edição/Impressão de Programação Final | D33: 1 | E33: 400 | F33: 2.5 | G33: =F33*E33*D33 -> 1000 | H33: 0 | I33: 0 | J33: 0 | K33: 0 | L33: 0 | M33: 0 | N33: =G33 -> 1000 | O33: 0 | P33: =H33+J33+L33+N33 -> 1000 | Q33: =I33+K33+M33+O33 -> 0
B34: Impressão de Cartazes | D34: 1 | E34: 400 | F34: 5 | G34: =F34*E34*D34 -> 2000 | H34: 1000 | I34: 1000 | J34: 0 | K34: 0 | L34: 0 | M34: 0 | N34: 1000 | O34: 0 | P34: =H34+J34+L34+N34 -> 2000 | Q34: =I34+K34+M34+O34 -> 1000
B35: Impressão de Faixas | D35: 1 | E35: 50 | F35: 20 | G35: =F35*E35*D35 -> 1000 | H35: 500 | I35: 500 | J35: 0 | K35: 0 | L35: 0 | M35: 0 | N35: 0 | O35: 0 | P35: =H35+J35+L35+N35 -> 500 | Q35: =I35+K35+M35+O35 -> 500
B36: Impressão Material do MiniCursos | D36: 1 | E36: 400 | F36: 5 | G36: =F36*E36*D36 -> 2000 | H36: 0 | I36: 0 | J36: 0 | K36: 0 | L36: 0 | M36: 0 | N36: =G36 -> 2000 | O36: 0 | P36: =H36+J36+L36+N36 -> 2000 | Q36: =I36+K36+M36+O36 -> 0
B37: Folder de Divulgação do Evento | D37: 1 | E37: 400 | F37: 2.5 | G37: =F37*E37*D37 -> 1000 | H37: 1000 | I37: 1000 | J37: 0 | K37: 0 | L37: 0 | M37: 0 | N37: 0 | O37: 0 | P37: =H37+J37+L37+N37 -> 1000 | Q37: =I37+K37+M37+O37 -> 1000
B38: Editoração dos Anais | D38: 1 | E38: 1 | F38: 4000 | G38: =F38*E38*D38 -> 4000 | H38: 0 | I38: 0 | J38: 0 | K38: 0 | L38: 0 | M38: 0 | N38: =G38 -> 4000 | O38: 0 | P38: =H38+J38+L38+N38 -> 4000 | Q38: =I38+K38+M38+O38 -> 0
B39: Produção de Mídia | D39: 1 | E39: 400 | F39: 5 | G39: =F39*E39*D39 -> 2000 | H39: 0 | I39: 0 | J39: 0 | K39: 0 | L39: 0 | M39: 0 | N39: =G39 -> 2000 | O39: 0 | P39: =H39+J39+L39+N39 -> 2000 | Q39: =I39+K39+M39+O39 -> 0
B40: Aquisição de Material de Consumo | D40: 1 | E40: 1 | F40: 9500 | G40: 9500 | H40: 0 | I40: 0 | J40: 0 | K40: 0 | L40: 0 | M40: 0 | N40: 0 | O40: 0 | P40: =H40+J40+L40+N40 -> 0 | Q40: =I40+K40+M40+O40 -> 0
B41: SubTotal | G41: =SUM(G33:G40) -> 22500 | H41: =SUM(H33:H40) -> 2500 | I41: =SUM(I33:I40) -> 2500 | J41: =SUM(J33:J40) -> 0 | K41: =SUM(K33:K40) -> 0 | L41: =SUM(L33:L40) -> 0 | M41: =SUM(M33:M40) -> 0 | N41: =SUM(N33:N40) -> 10000 | ... Q41: =SUM(Q33:Q40) -> 2500
B43: Serviços de Terceiros | D43: Unid. | E43: Quant. | F43: vl. Unit. | G43: Total Estimado | H43: FAPEAM | J43: CAPES | L43: CGI-BR | N43: CNPq | P43: Total Solicitado | Q43: Total Atendido
B44: Item | H44: Solicitado | I44: Atendido | J44: Solicitado | K44: Atendido | L44: Solicitado | M44: Atendido | N44: Solicitado | O44: Atendido
B45: Confecção de Camisas | D45: 1 | E45: 400 | F45: 18 | G45: =F45*E45*D45 -> 7200 | H45: 5940 | I45: 5940 | J45: 0 | K45: 0 | L45: 0 | M45: 0 | N45: 0 | O45: 0 | P45: =H45+J45+L45+N45 -> 5940 | Q45: =I45+K45+M45+O45 -> 5940
...

Sheet Receitas
A1: Receitas SBSeg 2013 | C1: Valores
A2: Comitê Gestor Internet | C2: 100000
A3: Inscrições | C3: 0
A4: CNPq | C4: 15000
A5: CAPES | C5: 45000
A6: Patrocínios | C6: 10000
A7: FAPEAM (Fundação de Amparo a Pesquisa do Estado do Amazonas) | C7: 29650
A8: SubTotal | C8: =SUM(C2:C7) -> 199650
